Workbook

Sheet gamerules
A1: Rule | B1: Description
A2: Turns | B2: The game will last 10 rounds, with each round consisting of a defender's turn followed by an attacker's turn.
A3: Budget | B3: Defender | C3: Attacker
B4: 5000 | C4: 5000
A5: Action per turn | B5: Both players will have 1 turn each round and will have to decide on whether or not they want to spend their budget to attack or defend Cyber City's districts.
A6: Defender's turn | B6: The defender will begin each turn deciding on whether or not they want spend their budget to increase protections on one or multiple districts.
B7: When applying cyber security tools to districts that have been compromised, a virtual dice will be rolled to determine the success rate of the defense tactic.
A8: Attacker's turn | B8: After the defender ends their turn, the attacker will have the chance to apply hacks to Cyber City establishments compromising Cyber City's critical infrastructure.
B9: When the attacker applies a hack, a virtual dice will be rolled to determine the success rate of the hack.
A10: Compromise Threshold | B10: When the attacker's hacks are successful, the district attacked will have their compromised percentage increased and the appropiate event will happen.
B11: When the defender's tools are successfull, the districts compromised percentage will decrease and the appropiate event will happen.
B12: When a district reaches a compromised percentage higher than 75% the district will shut down for the remainder of the game.

Sheet gameplc-mappings
A1: Power (10.10.10.1)
A2: Coil | B2: Status | C2: Mapping
A3: 0 | B3: FALSE | C3: Business District
A4: 1 | B4: FALSE | C4: Hospital
A5: 2 | B5: FALSE | C5: Police / Fire
A6: 3 | B6: FALSE | C6: Industrial Area
A7: 4 | B7: FALSE | C7: University
A8: 5 | B8: FALSE | C8: Residential
A10: Hospital (10.10.10.2)
A11: Coil | B11: Status | C11: Mapping
A12: 0 | B12: FALSE | C12: Power
A13: 1 | B13: FALSE | C13: Generator Running
A15: Police/Fire (10.10.10.3)
A16: Coil | B16: Status | C16: Mapping
A17: 0 | B17: FALSE | C17: Power
A18: 1 | B18: FALSE | C18: Generator Running
A20: Traffic (10.10.10.4)
A21: Coil | B21: Status | C21: Mapping
A22: 0 | B22: FALSE | C22: Green Light NS
A23: 1 | B23: FALSE | C23: Yellow Light NS
A24: 2 | B24: FALSE | C24: Red Light NS
A25: 3 | B25: FALSE | C25: Green Light EW
A26: 4 | B26: FALSE | C26: Yellow Light EW
A27: 5 | B27: FALSE | C27: Red Light EW

Sheet gamedistricts
A1: District | B1: University | C1: Housing/Gov't | D1: Business/Commercial | E1: Industry/Manufacturing/Transportation | F1: Healthcare | G1: Police/Fire
A2: Compromised Level | B2: =SUM(-B61+B31) -> -0.25 | C2: =SUM(-C61+C31) -> -0.6 | D2: =SUM(-D61+D31) -> -0.4 | E2: =SUM(-E61+E31) -> -0.3 | F2: =SUM(-F61+F31) -> -0.3 | G2: =SUM(-G61+G31) -> -0.5
A3: Attacks
A4: Man in the Middle (Steal Data) | B4: FALSE | C4: FALSE | D4: FALSE | E4: FALSE | F4: FALSE | G4: FALSE
A5: Malware (Steal Data) | B5: FALSE | C5: FALSE | D5: FALSE | E5: FALSE | F5: FALSE | G5: FALSE
A6: DDoS (Control) | B6: FALSE | C6: FALSE | D6: FALSE | E6: FALSE | F6: FALSE | G6: FALSE
A7: Phishing (Steal Data) | B7: FALSE | C7: FALSE | D7: FALSE | E7: FALSE | F7: FALSE | G7: FALSE
A8: Trojan (Control) | B8: FALSE | C8: FALSE | D8: FALSE | E8: FALSE | F8: FALSE | G8: FALSE
A9: Password Attack (Steal Data) | B9: FALSE | C9: FALSE | D9: FALSE | E9: FALSE | F9: FALSE | G9: FALSE
A10: Ransomware (Control) | B10: FALSE | C10: FALSE | D10: FALSE | E10: FALSE | F10: FALSE | G10: FALSE
A11: Attacks Cost | B11: =B21 -> 0 | C11: =C21 -> 0 | D11: =D21 -> 0 | E11: =E21 -> 0 | F11: =F21 -> 0 | G11: =G21 -> 0
A13: RAW COST
B14: =IF(B4, IFERROR(VLOOKUP($A4,dataroles!$A$4:$C$10, 2, FALSE), FALSE)) -> FALSE | C14: =IF(C4, IFERROR(VLOOKUP($A4,dataroles!$A$4:$C$10, 2, FALSE), FALSE)) -> FALSE | D14: =IF(D4, IFERROR(VLOOKUP($A4,dataroles!$A$4:$C$10, 2, FALSE), FALSE)) -> FALSE | E14: =IF(E4, IFERROR(VLOOKUP($A4,dataroles!$A$4:$C$10, 2, FALSE), FALSE)) -> FALSE | F14: =IF(F4, IFERROR(VLOOKUP($A4,dataroles!$A$4:$C$10, 2, FALSE), FALSE)) -> FALSE | G14: =IF(G4, IFERROR(VLOOKUP($A4,dataroles!$A$4:$C$10, 2, FALSE), FALSE)) -> FALSE
B15: =IF(B5, IFERROR(VLOOKUP($A5,dataroles!$A$4:$C$10, 2, FALSE), FALSE)) -> FALSE | C15: =IF(C5, IFERROR(VLOOKUP($A5,dataroles!$A$4:$C$10, 2, FALSE), FALSE)) -> FALSE | D15: =IF(D5, IFERROR(VLOOKUP($A5,dataroles!$A$4:$C$10, 2, FALSE), FALSE)) -> FALSE | E15: =IF(E5, IFERROR(VLOOKUP($A5,dataroles!$A$4:$C$10, 2, FALSE), FALSE)) -> FALSE | F15: =IF(F5, IFERROR(VLOOKUP($A5,dataroles!$A$4:$C$10, 2, FALSE), FALSE)) -> FALSE | G15: =IF(G5, IFERROR(VLOOKUP($A5,dataroles!$A$4:$C$10, 2, FALSE), FALSE)) -> FALSE
B16: =IF(B6, IFERROR(VLOOKUP($A6,dataroles!$A$4:$C$10, 2, FALSE), FALSE)) -> FALSE | C16: =IF(C6, IFERROR(VLOOKUP($A6,dataroles!$A$4:$C$10, 2, FALSE), FALSE)) -> FALSE | D16: =IF(D6, IFERROR(VLOOKUP($A6,dataroles!$A$4:$C$10, 2, FALSE), FALSE)) -> FALSE | E16: =IF(E6, IFERROR(VLOOKUP($A6,dataroles!$A$4:$C$10, 2, FALSE), FALSE)) -> FALSE | F16: =IF(F6, IFERROR(VLOOKUP($A6,dataroles!$A$4:$C$10, 2, FALSE), FALSE)) -> FALSE | G16: =IF(G6, IFERROR(VLOOKUP($A6,dataroles!$A$4:$C$10, 2, FALSE), FALSE)) -> FALSE
B17: =IF(B7, IFERROR(VLOOKUP($A7,dataroles!$A$4:$C$10, 2, FALSE), FALSE)) -> FALSE | C17: =IF(C7, IFERROR(VLOOKUP($A7,dataroles!$A$4:$C$10, 2, FALSE), FALSE)) -> FALSE | D17: =IF(D7, IFERROR(VLOOKUP($A7,dataroles!$A$4:$C$10, 2, FALSE), FALSE)) -> FALSE | E17: =IF(E7, IFERROR(VLOOKUP($A7,dataroles!$A$4:$C$10, 2, FALSE), FALSE)) -> FALSE | F17: =IF(F7, IFERROR(VLOOKUP($A7,dataroles!$A$4:$C$10, 2, FALSE), FALSE)) -> FALSE | G17: =IF(G7, IFERROR(VLOOKUP($A7,dataroles!$A$4:$C$10, 2, FALSE), FALSE)) -> FALSE
B18: =IF(B8, IFERROR(VLOOKUP($A8,dataroles!$A$4:$C$10, 2, FALSE), FALSE)) -> FALSE | C18: =IF(C8, IFERROR(VLOOKUP($A8,dataroles!$A$4:$C$10, 2, FALSE), FALSE)) -> FALSE | D18: =IF(D8, IFERROR(VLOOKUP($A8,dataroles!$A$4:$C$10, 2, FALSE), FALSE)) -> FALSE | E18: =IF(E8, IFERROR(VLOOKUP($A8,dataroles!$A$4:$C$10, 2, FALSE), FALSE)) -> FALSE | F18: =IF(F8, IFERROR(VLOOKUP($A8,dataroles!$A$4:$C$10, 2, FALSE), FALSE)) -> FALSE | G18: =IF(G8, IFERROR(VLOOKUP($A8,dataroles!$A$4:$C$10, 2, FALSE), FALSE)) -> FALSE
B19: =IF(B9, IFERROR(VLOOKUP($A9,dataroles!$A$4:$C$10, 2, FALSE), FALSE)) -> FALSE | C19: =IF(C9, IFERROR(VLOOKUP($A9,dataroles!$A$4:$C$10, 2, FALSE), FALSE)) -> FALSE | D19: =IF(D9, IFERROR(VLOOKUP($A9,dataroles!$A$4:$C$10, 2, FALSE), FALSE)) -> FALSE | E19: =IF(E9, IFERROR(VLOOKUP($A9,dataroles!$A$4:$C$10, 2, FALSE), FALSE)) -> FALSE | F19: =IF(F9, IFERROR(VLOOKUP($A9,dataroles!$A$4:$C$10, 2, FALSE), FALSE)) -> FALSE | G19: =IF(G9, IFERROR(VLOOKUP($A9,dataroles!$A$4:$C$10, 2, FALSE), FALSE)) -> FALSE
B20: =IF(B10, IFERROR(VLOOKUP($A10,dataroles!$A$4:$C$10, 2, FALSE), FALSE)) -> FALSE | C20: =IF(C10, IFERROR(VLOOKUP($A10,dataroles!$A$4:$C$10, 2, FALSE), FALSE)) -> FALSE | D20: =IF(D10, IFERROR(VLOOKUP($A10,dataroles!$A$4:$C$10, 2, FALSE), FALSE)) -> FALSE | E20: =IF(E10, IFERROR(VLOOKUP($A10,dataroles!$A$4:$C$10, 2, FALSE), FALSE)) -> FALSE | F20: =IF(F10, IFERROR(VLOOKUP($A10,dataroles!$A$4:$C$10, 2, FALSE), FALSE)) -> FALSE | G20: =IF(G10, IFERROR(VLOOKUP($A10,dataroles!$A$4:$C$10, 2, FALSE), FALSE)) -> FALSE
A21: RAW COST SUM | B21: =SUM(B14:B20) -> 0 | C21: =SUM(C14:C20) -> 0 | D21: =SUM(D14:D20) -> 0 | E21: =SUM(E14:E20) -> 0 | F21: =SUM(F14:F20) -> 0 | G21: =SUM(G14:G20) -> 0
A23: RAW MODIFIER
B24: =IFERROR(__xludf.DUMMYFUNCTION("IF(B4, IF( VLOOKUP(ARRAYFORMULA(VLOOKUP($A4, QUERY(dataability_matches!$A$2:$C$8, ""SELECT B, A, C""), 2, False)), $A$34:$G$40, 2, False), VLOOKUP($A4 ,dataroles!$A$4:$C$10, 3, False)*ARRAYFORMULA(VLOOKUP($A4, QUERY(dataability_matches!$A$2:$C$8, ""SELEC"&"T B, A, C""), 3, False)), VLOOKUP($A4 ,dataroles!$A$4:$C$10, 3, False)))"),FALSE) -> FALSE | C24: =IFERROR(__xludf.DUMMYFUNCTION("IF(C4, IF( VLOOKUP(ARRAYFORMULA(VLOOKUP($A4, QUERY(dataability_matches!$A$2:$C$8, ""SELECT B, A, C""), 2, False)), $A$34:$G$40, 3, False), VLOOKUP($A4 ,dataroles!$A$4:$C$10, 3, False)*ARRAYFORMULA(VLOOKUP($A4, QUERY(dataability_matches!$A$2:$C$8, ""SELEC"&"T B, A, C""), 3, False)), VLOOKUP($A4 ,dataroles!$A$4:$C$10, 3, False)))"),FALSE) -> FALSE | D24: =IFERROR(__xludf.DUMMYFUNCTION("IF(D4, IF( VLOOKUP(ARRAYFORMULA(VLOOKUP($A4, QUERY(dataability_matches!$A$2:$C$8, ""SELECT B, A, C""), 2, False)), $A$34:$G$40, 4, False), VLOOKUP($A4 ,dataroles!$A$4:$C$10, 3, False)*ARRAYFORMULA(VLOOKUP($A4, QUERY(dataability_matches!$A$2:$C$8, ""SELEC"&"T B, A, C""), 3, False)), VLOOKUP($A4 ,dataroles!$A$4:$C$10, 3, False)))"),FALSE) -> FALSE | E24: =IFERROR(__xludf.DUMMYFUNCTION("IF(E4, IF( VLOOKUP(ARRAYFORMULA(VLOOKUP($A4, QUERY(dataability_matches!$A$2:$C$8, ""SELECT B, A, C""), 2, False)), $A$34:$G$40, 5, False), VLOOKUP($A4 ,dataroles!$A$4:$C$10, 3, False)*ARRAYFORMULA(VLOOKUP($A4, QUERY(dataability_matches!$A$2:$C$8, ""SELEC"&"T B, A, C""), 3, False)), VLOOKUP($A4 ,dataroles!$A$4:$C$10, 3, False)))"),FALSE) -> FALSE | F24: =IFERROR(__xludf.DUMMYFUNCTION("IF(F4, IF( VLOOKUP(ARRAYFORMULA(VLOOKUP($A4, QUERY(dataability_matches!$A$2:$C$8, ""SELECT B, A, C""), 2, False)), $A$34:$G$40, 6, False), VLOOKUP($A4 ,dataroles!$A$4:$C$10, 3, False)*ARRAYFORMULA(VLOOKUP($A4, QUERY(dataability_matches!$A$2:$C$8, ""SELEC"&"T B, A, C""), 3, False)), VLOOKUP($A4 ,dataroles!$A$4:$C$10, 3, False)))"),FALSE) -> FALSE | G24: =IFERROR(__xludf.DUMMYFUNCTION("IF(G4, IF( VLOOKUP(ARRAYFORMULA(VLOOKUP($A4, QUERY(dataability_matches!$A$2:$C$8, ""SELECT B, A, C""), 2, False)), $A$34:$G$40, 7, False), VLOOKUP($A4 ,dataroles!$A$4:$C$10, 3, False)*ARRAYFORMULA(VLOOKUP($A4, QUERY(dataability_matches!$A$2:$C$8, ""SELEC"&"T B, A, C""), 3, False)), VLOOKUP($A4 ,dataroles!$A$4:$C$10, 3, False)))"),FALSE) -> FALSE
B25: =IFERROR(__xludf.DUMMYFUNCTION("IF(B5, IF( VLOOKUP(ARRAYFORMULA(VLOOKUP($A5, QUERY(dataability_matches!$A$2:$C$8, ""SELECT B, A, C""), 2, False)), $A$34:$G$40, 2, False), VLOOKUP($A5 ,dataroles!$A$4:$C$10, 3, False)*ARRAYFORMULA(VLOOKUP($A5, QUERY(dataability_matches!$A$2:$C$8, ""SELEC"&"T B, A, C""), 3, False)), VLOOKUP($A5 ,dataroles!$A$4:$C$10, 3, False)))"),FALSE) -> FALSE | C25: =IFERROR(__xludf.DUMMYFUNCTION("IF(C5, IF( VLOOKUP(ARRAYFORMULA(VLOOKUP($A5, QUERY(dataability_matches!$A$2:$C$8, ""SELECT B, A, C""), 2, False)), $A$34:$G$40, 3, False), VLOOKUP($A5 ,dataroles!$A$4:$C$10, 3, False)*ARRAYFORMULA(VLOOKUP($A5, QUERY(dataability_matches!$A$2:$C$8, ""SELEC"&"T B, A, C""), 3, False)), VLOOKUP($A5 ,dataroles!$A$4:$C$10, 3, False)))"),FALSE) -> FALSE | D25: =IFERROR(__xludf.DUMMYFUNCTION("IF(D5, IF( VLOOKUP(ARRAYFORMULA(VLOOKUP($A5, QUERY(dataability_matches!$A$2:$C$8, ""SELECT B, A, C""), 2, False)), $A$34:$G$40, 4, False), VLOOKUP($A5 ,dataroles!$A$4:$C$10, 3, False)*ARRAYFORMULA(VLOOKUP($A5, QUERY(dataability_matches!$A$2:$C$8, ""SELEC"&"T B, A, C""), 3, False)), VLOOKUP($A5 ,dataroles!$A$4:$C$10, 3, False)))"),FALSE) -> FALSE | E25: =IFERROR(__xludf.DUMMYFUNCTION("IF(E5, IF( VLOOKUP(ARRAYFORMULA(VLOOKUP($A5, QUERY(dataability_matches!$A$2:$C$8, ""SELECT B, A, C""), 2, False)), $A$34:$G$40, 5, False), VLOOKUP($A5 ,dataroles!$A$4:$C$10, 3, False)*ARRAYFORMULA(VLOOKUP($A5, QUERY(dataability_matches!$A$2:$C$8, ""SELEC"&"T B, A, C""), 3, False)), VLOOKUP($A5 ,dataroles!$A$4:$C$10, 3, False)))"),FALSE) -> FALSE | F25: =IFERROR(__xludf.DUMMYFUNCTION("IF(F5, IF( VLOOKUP(ARRAYFORMULA(VLOOKUP($A5, QUERY(dataability_matches!$A$2:$C$8, ""SELECT B, A, C""), 2, False)), $A$34:$G$40, 6, False), VLOOKUP($A5 ,dataroles!$A$4:$C$10, 3, False)*ARRAYFORMULA(VLOOKUP($A5, QUERY(dataability_matches!$A$2:$C$8, ""SELEC"&"T B, A, C""), 3, False)), VLOOKUP($A5 ,dataroles!$A$4:$C$10, 3, False)))"),FALSE) -> FALSE | G25: =IFERROR(__xludf.DUMMYFUNCTION("IF(G5, IF( VLOOKUP(ARRAYFORMULA(VLOOKUP($A5, QUERY(dataability_matches!$A$2:$C$8, ""SELECT B, A, C""), 2, False)), $A$34:$G$40, 7, False), VLOOKUP($A5 ,dataroles!$A$4:$C$10, 3, False)*ARRAYFORMULA(VLOOKUP($A5, QUERY(dataability_matches!$A$2:$C$8, ""SELEC"&"T B, A, C""), 3, False)), VLOOKUP($A5 ,dataroles!$A$4:$C$10, 3, False)))"),FALSE) -> FALSE
B26: =IFERROR(__xludf.DUMMYFUNCTION("IF(B6, IF( VLOOKUP(ARRAYFORMULA(VLOOKUP($A6, QUERY(dataability_matches!$A$2:$C$8, ""SELECT B, A, C""), 2, False)), $A$34:$G$40, 2, False), VLOOKUP($A6 ,dataroles!$A$4:$C$10, 3, False)*ARRAYFORMULA(VLOOKUP($A6, QUERY(dataability_matches!$A$2:$C$8, ""SELEC"&"T B, A, C""), 3, False)), VLOOKUP($A6 ,dataroles!$A$4:$C$10, 3, False)))"),FALSE) -> FALSE | C26: =IFERROR(__xludf.DUMMYFUNCTION("IF(C6, IF( VLOOKUP(ARRAYFORMULA(VLOOKUP($A6, QUERY(dataability_matches!$A$2:$C$8, ""SELECT B, A, C""), 2, False)), $A$34:$G$40, 3, False), VLOOKUP($A6 ,dataroles!$A$4:$C$10, 3, False)*ARRAYFORMULA(VLOOKUP($A6, QUERY(dataability_matches!$A$2:$C$8, ""SELEC"&"T B, A, C""), 3, False)), VLOOKUP($A6 ,dataroles!$A$4:$C$10, 3, False)))"),FALSE) -> FALSE | D26: =IFERROR(__xludf.DUMMYFUNCTION("IF(D6, IF( VLOOKUP(ARRAYFORMULA(VLOOKUP($A6, QUERY(dataability_matches!$A$2:$C$8, ""SELECT B, A, C""), 2, False)), $A$34:$G$40, 4, False), VLOOKUP($A6 ,dataroles!$A$4:$C$10, 3, False)*ARRAYFORMULA(VLOOKUP($A6, QUERY(dataability_matches!$A$2:$C$8, ""SELEC"&"T B, A, C""), 3, False)), VLOOKUP($A6 ,dataroles!$A$4:$C$10, 3, False)))"),FALSE) -> FALSE | E26: =IFERROR(__xludf.DUMMYFUNCTION("IF(E6, IF( VLOOKUP(ARRAYFORMULA(VLOOKUP($A6, QUERY(dataability_matches!$A$2:$C$8, ""SELECT B, A, C""), 2, False)), $A$34:$G$40, 5, False), VLOOKUP($A6 ,dataroles!$A$4:$C$10, 3, False)*ARRAYFORMULA(VLOOKUP($A6, QUERY(dataability_matches!$A$2:$C$8, ""SELEC"&"T B, A, C""), 3, False)), VLOOKUP($A6 ,dataroles!$A$4:$C$10, 3, False)))"),FALSE) -> FALSE | F26: =IFERROR(__xludf.DUMMYFUNCTION("IF(F6, IF( VLOOKUP(ARRAYFORMULA(VLOOKUP($A6, QUERY(dataability_matches!$A$2:$C$8, ""SELECT B, A, C""), 2, False)), $A$34:$G$40, 6, False), VLOOKUP($A6 ,dataroles!$A$4:$C$10, 3, False)*ARRAYFORMULA(VLOOKUP($A6, QUERY(dataability_matches!$A$2:$C$8, ""SELEC"&"T B, A, C""), 3, False)), VLOOKUP($A6 ,dataroles!$A$4:$C$10, 3, False)))"),FALSE) -> FALSE | G26: =IFERROR(__xludf.DUMMYFUNCTION("IF(G6, IF( VLOOKUP(ARRAYFORMULA(VLOOKUP($A6, QUERY(dataability_matches!$A$2:$C$8, ""SELECT B, A, C""), 2, False)), $A$34:$G$40, 7, False), VLOOKUP($A6 ,dataroles!$A$4:$C$10, 3, False)*ARRAYFORMULA(VLOOKUP($A6, QUERY(dataability_matches!$A$2:$C$8, ""SELEC"&"T B, A, C""), 3, False)), VLOOKUP($A6 ,dataroles!$A$4:$C$10, 3, False)))"),FALSE) -> FALSE
B27: =IFERROR(__xludf.DUMMYFUNCTION("IF(B7, IF( VLOOKUP(ARRAYFORMULA(VLOOKUP($A7, QUERY(dataability_matches!$A$2:$C$8, ""SELECT B, A, C""), 2, False)), $A$34:$G$40, 2, False), VLOOKUP($A7 ,dataroles!$A$4:$C$10, 3, False)*ARRAYFORMULA(VLOOKUP($A7, QUERY(dataability_matches!$A$2:$C$8, ""SELEC"&"T B, A, C""), 3, False)), VLOOKUP($A7 ,dataroles!$A$4:$C$10, 3, False)))"),FALSE) -> FALSE | C27: =IFERROR(__xludf.DUMMYFUNCTION("IF(C7, IF( VLOOKUP(ARRAYFORMULA(VLOOKUP($A7, QUERY(dataability_matches!$A$2:$C$8, ""SELECT B, A, C""), 2, False)), $A$34:$G$40, 3, False), VLOOKUP($A7 ,dataroles!$A$4:$C$10, 3, False)*ARRAYFORMULA(VLOOKUP($A7, QUERY(dataability_matches!$A$2:$C$8, ""SELEC"&"T B, A, C""), 3, False)), VLOOKUP($A7 ,dataroles!$A$4:$C$10, 3, False)))"),FALSE) -> FALSE | D27: =IFERROR(__xludf.DUMMYFUNCTION("IF(D7, IF( VLOOKUP(ARRAYFORMULA(VLOOKUP($A7, QUERY(dataability_matches!$A$2:$C$8, ""SELECT B, A, C""), 2, False)), $A$34:$G$40, 4, False), VLOOKUP($A7 ,dataroles!$A$4:$C$10, 3, False)*ARRAYFORMULA(VLOOKUP($A7, QUERY(dataability_matches!$A$2:$C$8, ""SELEC"&"T B, A, C""), 3, False)), VLOOKUP($A7 ,dataroles!$A$4:$C$10, 3, False)))"),FALSE) -> FALSE | E27: =IFERROR(__xludf.DUMMYFUNCTION("IF(E7, IF( VLOOKUP(ARRAYFORMULA(VLOOKUP($A7, QUERY(dataability_matches!$A$2:$C$8, ""SELECT B, A, C""), 2, False)), $A$34:$G$40, 5, False), VLOOKUP($A7 ,dataroles!$A$4:$C$10, 3, False)*ARRAYFORMULA(VLOOKUP($A7, QUERY(dataability_matches!$A$2:$C$8, ""SELEC"&"T B, A, C""), 3, False)), VLOOKUP($A7 ,dataroles!$A$4:$C$10, 3, False)))"),FALSE) -> FALSE | F27: =IFERROR(__xludf.DUMMYFUNCTION("IF(F7, IF( VLOOKUP(ARRAYFORMULA(VLOOKUP($A7, QUERY(dataability_matches!$A$2:$C$8, ""SELECT B, A, C""), 2, False)), $A$34:$G$40, 6, False), VLOOKUP($A7 ,dataroles!$A$4:$C$10, 3, False)*ARRAYFORMULA(VLOOKUP($A7, QUERY(dataability_matches!$A$2:$C$8, ""SELEC"&"T B, A, C""), 3, False)), VLOOKUP($A7 ,dataroles!$A$4:$C$10, 3, False)))"),FALSE) -> FALSE | G27: =IFERROR(__xludf.DUMMYFUNCTION("IF(G7, IF( VLOOKUP(ARRAYFORMULA(VLOOKUP($A7, QUERY(dataability_matches!$A$2:$C$8, ""SELECT B, A, C""), 2, False)), $A$34:$G$40, 7, False), VLOOKUP($A7 ,dataroles!$A$4:$C$10, 3, False)*ARRAYFORMULA(VLOOKUP($A7, QUERY(dataability_matches!$A$2:$C$8, ""SELEC"&"T B, A, C""), 3, False)), VLOOKUP($A7 ,dataroles!$A$4:$C$10, 3, False)))"),FALSE) -> FALSE
B28: =IFERROR(__xludf.DUMMYFUNCTION("IF(B8, IF( VLOOKUP(ARRAYFORMULA(VLOOKUP($A8, QUERY(dataability_matches!$A$2:$C$8, ""SELECT B, A, C""), 2, False)), $A$34:$G$40, 2, False), VLOOKUP($A8 ,dataroles!$A$4:$C$10, 3, False)*ARRAYFORMULA(VLOOKUP($A8, QUERY(dataability_matches!$A$2:$C$8, ""SELEC"&"T B, A, C""), 3, False)), VLOOKUP($A8 ,dataroles!$A$4:$C$10, 3, False)))"),FALSE) -> FALSE | C28: =IFERROR(__xludf.DUMMYFUNCTION("IF(C8, IF( VLOOKUP(ARRAYFORMULA(VLOOKUP($A8, QUERY(dataability_matches!$A$2:$C$8, ""SELECT B, A, C""), 2, False)), $A$34:$G$40, 3, False), VLOOKUP($A8 ,dataroles!$A$4:$C$10, 3, False)*ARRAYFORMULA(VLOOKUP($A8, QUERY(dataability_matches!$A$2:$C$8, ""SELEC"&"T B, A, C""), 3, False)), VLOOKUP($A8 ,dataroles!$A$4:$C$10, 3, False)))"),FALSE) -> FALSE | D28: =IFERROR(__xludf.DUMMYFUNCTION("IF(D8, IF( VLOOKUP(ARRAYFORMULA(VLOOKUP($A8, QUERY(dataability_matches!$A$2:$C$8, ""SELECT B, A, C""), 2, False)), $A$34:$G$40, 4, False), VLOOKUP($A8 ,dataroles!$A$4:$C$10, 3, False)*ARRAYFORMULA(VLOOKUP($A8, QUERY(dataability_matches!$A$2:$C$8, ""SELEC"&"T B, A, C""), 3, False)), VLOOKUP($A8 ,dataroles!$A$4:$C$10, 3, False)))"),FALSE) -> FALSE | E28: =IFERROR(__xludf.DUMMYFUNCTION("IF(E8, IF( VLOOKUP(ARRAYFORMULA(VLOOKUP($A8, QUERY(dataability_matches!$A$2:$C$8, ""SELECT B, A, C""), 2, False)), $A$34:$G$40, 5, False), VLOOKUP($A8 ,dataroles!$A$4:$C$10, 3, False)*ARRAYFORMULA(VLOOKUP($A8, QUERY(dataability_matches!$A$2:$C$8, ""SELEC"&"T B, A, C""), 3, False)), VLOOKUP($A8 ,dataroles!$A$4:$C$10, 3, False)))"),FALSE) -> FALSE | F28: =IFERROR(__xludf.DUMMYFUNCTION("IF(F8, IF( VLOOKUP(ARRAYFORMULA(VLOOKUP($A8, QUERY(dataability_matches!$A$2:$C$8, ""SELECT B, A, C""), 2, False)), $A$34:$G$40, 6, False), VLOOKUP($A8 ,dataroles!$A$4:$C$10, 3, False)*ARRAYFORMULA(VLOOKUP($A8, QUERY(dataability_matches!$A$2:$C$8, ""SELEC"&"T B, A, C""), 3, False)), VLOOKUP($A8 ,dataroles!$A$4:$C$10, 3, False)))"),FALSE) -> FALSE | G28: =IFERROR(__xludf.DUMMYFUNCTION("IF(G8, IF( VLOOKUP(ARRAYFORMULA(VLOOKUP($A8, QUERY(dataability_matches!$A$2:$C$8, ""SELECT B, A, C""), 2, False)), $A$34:$G$40, 7, False), VLOOKUP($A8 ,dataroles!$A$4:$C$10, 3, False)*ARRAYFORMULA(VLOOKUP($A8, QUERY(dataability_matches!$A$2:$C$8, ""SELEC"&"T B, A, C""), 3, False)), VLOOKUP($A8 ,dataroles!$A$4:$C$10, 3, False)))"),FALSE) -> FALSE
B29: =IFERROR(__xludf.DUMMYFUNCTION("IF(B9, IF( VLOOKUP(ARRAYFORMULA(VLOOKUP($A9, QUERY(dataability_matches!$A$2:$C$8, ""SELECT B, A, C""), 2, False)), $A$34:$G$40, 2, False), VLOOKUP($A9 ,dataroles!$A$4:$C$10, 3, False)*ARRAYFORMULA(VLOOKUP($A9, QUERY(dataability_matches!$A$2:$C$8, ""SELEC"&"T B, A, C""), 3, False)), VLOOKUP($A9 ,dataroles!$A$4:$C$10, 3, False)))"),FALSE) -> FALSE | C29: =IFERROR(__xludf.DUMMYFUNCTION("IF(C9, IF( VLOOKUP(ARRAYFORMULA(VLOOKUP($A9, QUERY(dataability_matches!$A$2:$C$8, ""SELECT B, A, C""), 2, False)), $A$34:$G$40, 3, False), VLOOKUP($A9 ,dataroles!$A$4:$C$10, 3, False)*ARRAYFORMULA(VLOOKUP($A9, QUERY(dataability_matches!$A$2:$C$8, ""SELEC"&"T B, A, C""), 3, False)), VLOOKUP($A9 ,dataroles!$A$4:$C$10, 3, False)))"),FALSE) -> FALSE | D29: =IFERROR(__xludf.DUMMYFUNCTION("IF(D9, IF( VLOOKUP(ARRAYFORMULA(VLOOKUP($A9, QUERY(dataability_matches!$A$2:$C$8, ""SELECT B, A, C""), 2, False)), $A$34:$G$40, 4, False), VLOOKUP($A9 ,dataroles!$A$4:$C$10, 3, False)*ARRAYFORMULA(VLOOKUP($A9, QUERY(dataability_matches!$A$2:$C$8, ""SELEC"&"T B, A, C""), 3, False)), VLOOKUP($A9 ,dataroles!$A$4:$C$10, 3, False)))"),FALSE) -> FALSE | E29: =IFERROR(__xludf.DUMMYFUNCTION("IF(E9, IF( VLOOKUP(ARRAYFORMULA(VLOOKUP($A9, QUERY(dataability_matches!$A$2:$C$8, ""SELECT B, A, C""), 2, False)), $A$34:$G$40, 5, False), VLOOKUP($A9 ,dataroles!$A$4:$C$10, 3, False)*ARRAYFORMULA(VLOOKUP($A9, QUERY(dataability_matches!$A$2:$C$8, ""SELEC"&"T B, A, C""), 3, False)), VLOOKUP($A9 ,dataroles!$A$4:$C$10, 3, False)))"),FALSE) -> FALSE | F29: =IFERROR(__xludf.DUMMYFUNCTION("IF(F9, IF( VLOOKUP(ARRAYFORMULA(VLOOKUP($A9, QUERY(dataability_matches!$A$2:$C$8, ""SELECT B, A, C""), 2, False)), $A$34:$G$40, 6, False), VLOOKUP($A9 ,dataroles!$A$4:$C$10, 3, False)*ARRAYFORMULA(VLOOKUP($A9, QUERY(dataability_matches!$A$2:$C$8, ""SELEC"&"T B, A, C""), 3, False)), VLOOKUP($A9 ,dataroles!$A$4:$C$10, 3, False)))"),FALSE) -> FALSE | G29: =IFERROR(__xludf.DUMMYFUNCTION("IF(G9, IF( VLOOKUP(ARRAYFORMULA(VLOOKUP($A9, QUERY(dataability_matches!$A$2:$C$8, ""SELECT B, A, C""), 2, False)), $A$34:$G$40, 7, False), VLOOKUP($A9 ,dataroles!$A$4:$C$10, 3, False)*ARRAYFORMULA(VLOOKUP($A9, QUERY(dataability_matches!$A$2:$C$8, ""SELEC"&"T B, A, C""), 3, False)), VLOOKUP($A9 ,dataroles!$A$4:$C$10, 3, False)))"),FALSE) -> FALSE
B30: =IFERROR(__xludf.DUMMYFUNCTION("IF(B10, IF( VLOOKUP(ARRAYFORMULA(VLOOKUP($A10, QUERY(dataability_matches!$A$2:$C$8, ""SELECT B, A, C""), 2, False)), $A$34:$G$40, 2, False), VLOOKUP($A10 ,dataroles!$A$4:$C$10, 3, False)*ARRAYFORMULA(VLOOKUP($A10, QUERY(dataability_matches!$A$2:$C$8, ""S"&"ELECT B, A, C""), 3, False)), VLOOKUP($A10 ,dataroles!$A$4:$C$10, 3, False)))"),FALSE) -> FALSE | C30: =IFERROR(__xludf.DUMMYFUNCTION("IF(C10, IF( VLOOKUP(ARRAYFORMULA(VLOOKUP($A10, QUERY(dataability_matches!$A$2:$C$8, ""SELECT B, A, C""), 2, False)), $A$34:$G$40, 3, False), VLOOKUP($A10 ,dataroles!$A$4:$C$10, 3, False)*ARRAYFORMULA(VLOOKUP($A10, QUERY(dataability_matches!$A$2:$C$8, ""S"&"ELECT B, A, C""), 3, False)), VLOOKUP($A10 ,dataroles!$A$4:$C$10, 3, False)))"),FALSE) -> FALSE | D30: =IFERROR(__xludf.DUMMYFUNCTION("IF(D10, IF( VLOOKUP(ARRAYFORMULA(VLOOKUP($A10, QUERY(dataability_matches!$A$2:$C$8, ""SELECT B, A, C""), 2, False)), $A$34:$G$40, 4, False), VLOOKUP($A10 ,dataroles!$A$4:$C$10, 3, False)*ARRAYFORMULA(VLOOKUP($A10, QUERY(dataability_matches!$A$2:$C$8, ""S"&"ELECT B, A, C""), 3, False)), VLOOKUP($A10 ,dataroles!$A$4:$C$10, 3, False)))"),FALSE) -> FALSE | E30: =IFERROR(__xludf.DUMMYFUNCTION("IF(E10, IF( VLOOKUP(ARRAYFORMULA(VLOOKUP($A10, QUERY(dataability_matches!$A$2:$C$8, ""SELECT B, A, C""), 2, False)), $A$34:$G$40, 5, False), VLOOKUP($A10 ,dataroles!$A$4:$C$10, 3, False)*ARRAYFORMULA(VLOOKUP($A10, QUERY(dataability_matches!$A$2:$C$8, ""S"&"ELECT B, A, C""), 3, False)), VLOOKUP($A10 ,dataroles!$A$4:$C$10, 3, False)))"),FALSE) -> FALSE | F30: =IFERROR(__xludf.DUMMYFUNCTION("IF(F10, IF( VLOOKUP(ARRAYFORMULA(VLOOKUP($A10, QUERY(dataability_matches!$A$2:$C$8, ""SELECT B, A, C""), 2, False)), $A$34:$G$40, 6, False), VLOOKUP($A10 ,dataroles!$A$4:$C$10, 3, False)*ARRAYFORMULA(VLOOKUP($A10, QUERY(dataability_matches!$A$2:$C$8, ""S"&"ELECT B, A, C""), 3, False)), VLOOKUP($A10 ,dataroles!$A$4:$C$10, 3, False)))"),FALSE) -> FALSE | G30: =IFERROR(__xludf.DUMMYFUNCTION("IF(G10, IF( VLOOKUP(ARRAYFORMULA(VLOOKUP($A10, QUERY(dataability_matches!$A$2:$C$8, ""SELECT B, A, C""), 2, False)), $A$34:$G$40, 7, False), VLOOKUP($A10 ,dataroles!$A$4:$C$10, 3, False)*ARRAYFORMULA(VLOOKUP($A10, QUERY(dataability_matches!$A$2:$C$8, ""S"&"ELECT B, A, C""), 3, False)), VLOOKUP($A10 ,dataroles!$A$4:$C$10, 3, False)))"),FALSE) -> FALSE
A31: RAW MODIFIER SUM | B31: =SUM(B24:B30)/100 -> 0 | C31: =SUM(C24:C30)/100 -> 0 | D31: =SUM(D24:D30)/100 -> 0 | E31: =SUM(E24:E30)/100 -> 0 | F31: =SUM(F24:F30)/100 -> 0 | G31: =SUM(G24:G30)/100 -> 0
A33: Protections
A34: Data Encryption | B34: FALSE | C34: FALSE | D34: FALSE | E34: FALSE | F34: FALSE | G34: FALSE
A35: Anti-Malware | B35: FALSE | C35: TRUE | D35: FALSE | E35: TRUE | F35: FALSE | G35: FALSE
A36: Firewall | B36: FALSE | C36: TRUE | D36: TRUE | E36: FALSE | F36: FALSE | G36: TRUE
A37: Trust Zones | B37: TRUE | C37: FALSE | D37: FALSE | E37: FALSE | F37: FALSE | G37: FALSE
A38: Honey Pot | B38: FALSE | C38: FALSE | D38: FALSE | E38: FALSE | F38: FALSE | G38: FALSE
A39: Multifactor Authentication | B39: TRUE | C39: FALSE | D39: TRUE | E39: FALSE | F39: TRUE | G39: FALSE
A40: Audit Devices & Assets | B40: FALSE | C40: FALSE | D40: FALSE | E40: FALSE | F40: TRUE | G40: TRUE
A41: Protections Cost | B41: =B51 -> 0 | C41: =C51 -> 0 | D41: =D51 -> 0 | E41: =E51 -> 0 | F41: =F51 -> 0 | G41: =G51 -> 0
A43: RAW COST
B44: =IF(B34, IFERROR(VLOOKUP($A34, dataroles!$D$4:$F$10, 2, FALSE), FALSE)) -> FALSE | C44: =IF(C34, IFERROR(VLOOKUP($A34, dataroles!$D$4:$F$10, 2, FALSE), FALSE)) -> FALSE | D44: =IF(D34, IFERROR(VLOOKUP($A34, dataroles!$D$4:$F$10, 2, FALSE), FALSE)) -> FALSE | E44: =IF(E34, IFERROR(VLOOKUP($A34, dataroles!$D$4:$F$10, 2, FALSE), FALSE)) -> FALSE | F44: =IF(F34, IFERROR(VLOOKUP($A34, dataroles!$D$4:$F$10, 2, FALSE), FALSE)) -> FALSE | G44: =IF(G34, IFERROR(VLOOKUP($A34, dataroles!$D$4:$F$10, 2, FALSE), FALSE)) -> FALSE
...

Sheet dataroles
A1: Attacker | D1: Defender
A2: Budget | B2: 5000 | D2: Budget | E2: 5000
A3: Ability | B3: Cost | C3: Compromise Modifier | D3: Ability | E3: Cost | F3: Compromise Modifier
A4: Man in the Middle (Steal Data) | B4: 300 | C4: 20 | D4: Data Encryption | E4: 300 | F4: 10
A5: Malware (Steal Data) | B5: 600 | C5: 60 | D5: Anti-Malware | E5: 600 | F5: 30
A6: DDoS (Control) | B6: 600 | C6: 60 | D6: Firewall | E6: 600 | F6: 30
A7: Phishing (Steal Data) | B7: 400 | C7: 30 | D7: Trust Zones | E7: 400 | F7: 15
A8: Trojan (Control) | B8: 500 | C8: 40 | D8: Honey Pot | E8: 500 | F8: 20
A9: Password Attack (Steal Data) | B9: 300 | C9: 20 | D9: Multifactor Authentication | E9: 300 | F9: 10
A10: Ransomware (Control) | B10: 500 | C10: 40 | D10: Audit Devices & Assets | E10: 500 | F10: 20

Sheet dataability_matches
A1: Defender Ability | B1: Attacker Ability | C1: Modifier Percentage
A2: Data Encryption | B2: Man in the Middle (Steal Data) | C2: 0.5
A3: Anti-Malware | B3: Malware (Steal Data) | C3: 0.5
A4: Firewall | B4: DDoS (Control) | C4: 0.5
A5: Trust Zones | B5: Phishing (Steal Data) | C5: 0.5
A6: Honey Pot | B6: Trojan (Control) | C6: 0.5
A7: Multifactor Authentication | B7: Password Attack (Steal Data) | C7: 0.5
A8: Audit Devices & Assets | B8: Ransomware (Control) | C8: 0.5

Sheet dataevents
A1: Event | B1: Alert Text | C1: Mode | D1: Effect | E1: Serverity | F1: Modes | G1: Effects | H1: Severity
A2: all_go | B2: Multiple accidents reported in the area. | C2: Negative | D2: Traffic - All Green | E2: High | F2: Positive | G2: Power-off | H2: Low
A3: cipher_text | B3: Data breach attempts have been blocked! | C3: Positive | D3: N/A | E3: Low | F3: Negative | G3: Power-on | H3: Medium
A4: grid_control | B4: Power has been restored! | C4: Positive | D4: Power-on | E4: Critical | G4: Generator-off | H4: High
A5: lights_out | B5: Multiple reports of a power outage! | C5: Negative | D5: Power-off | E5: Critical | G5: Generator-on | H5: Critical
A6: normal_traffic | B6: Road traffic is flowing smoothly! | C6: Positive | D6: Traffic - Normal | E6: Medium | G6: Traffic - All Green
A7: power_source | B7: Generators are up and running! | C7: Positive | D7: Generator-on | E7: Critical | G7: Traffic - All Red
A8: rouge_access | B8: Network traffic is being manipulated! | C8: Negative | D8: Power-off | E8: Critical | G8: Trafiic - Flashing Red
A9: stopped_traffic | B9: Traffic is backed up on multiple streets! | C9: Negative | D9: Traffic - All Red | E9: High | G9: Traffic - Normal
A10: sus_traffic | B10: Road traffic is acting suspicious! | C10: Negative | D10: Traffic - All Red | E10: High | G10: Traffic - Random
A11: transformer_down | B11: Back-up Generators were destroyed! | C11: Negative | D11: Generator-off | E11: Critical
A12: unknown_access | B12: Unknown access detected! | C12: Negative | D12: N/A | E12: Medium
A13: secure_network | B13: District is completely protected! | C13: Positive | D13: Power-on | E13: High
A14: activity_detected | B14: District under surveillance! | C14: Positive | D14: Traffic - Normal | E14: Low
C15: N/A | D15: N/A | E15: N/A
C16: N/A | D16: N/A | E16: N/A
C17: N/A | D17: N/A | E17: N/A
C18: N/A | D18: N/A | E18: N/A
C19: N/A | D19: N/A | E19: N/A
C20: N/A | D20: N/A | E20: N/A
C21: N/A | D21: N/A | E21: N/A
C22: N/A | D22: N/A | E22: N/A
C23: N/A | D23: N/A | E23: N/A
C24: N/A | D24: N/A | E24: N/A
C25: N/A | D25: N/A | E25: N/A
C26: N/A | D26: N/A | E26: N/A
... C99: N/A | D99: N/A | E99: N/A
C100: N/A | D100: N/A | E100: N/A | F100: N/A | G100: N/A | H100: N/A
